Workbook

Sheet oat_1
A1: ID | B1: Grain weight - g|CO_350:0005123 | C1: observationUnitName
A2: 734992 | B2: 626.7 | C2: =VLOOKUP(A2,name_ID!$A$2:$B$401,2,FALSE) -> B4I_2025_NY_5299
A3: 735007 | B3: 531.1 | C3: =VLOOKUP(A3,name_ID!$A$2:$B$401,2,FALSE) -> B4I_2025_NY_5151
A4: 734844 | B4: 440.7 | C4: =VLOOKUP(A4,name_ID!$A$2:$B$401,2,FALSE) -> B4I_2025_NY_5105
A5: 734737 | B5: 696.4 | C5: =VLOOKUP(A5,name_ID!$A$2:$B$401,2,FALSE) -> B4I_2025_NY_5156
A6: 734945 | B6: 496.6 | C6: =VLOOKUP(A6,name_ID!$A$2:$B$401,2,FALSE) -> B4I_2025_NY_5045
A7: 734861 | B7: 563.1 | C7: =VLOOKUP(A7,name_ID!$A$2:$B$401,2,FALSE) -> B4I_2025_NY_5153
A8: 734853 | B8: 615.1 | C8: =VLOOKUP(A8,name_ID!$A$2:$B$401,2,FALSE) -> B4I_2025_NY_5280
A9: 735096 | B9: 754.9 | C9: =VLOOKUP(A9,name_ID!$A$2:$B$401,2,FALSE) -> B4I_2025_NY_5006
A10: 734929 | B10: 506 | C10: =VLOOKUP(A10,name_ID!$A$2:$B$401,2,FALSE) -> B4I_2025_NY_5120
A11: 735026 | B11: 429.9 | C11: =VLOOKUP(A11,name_ID!$A$2:$B$401,2,FALSE) -> B4I_2025_NY_5073
A12: 735053 | B12: 535 | C12: =VLOOKUP(A12,name_ID!$A$2:$B$401,2,FALSE) -> B4I_2025_NY_5197
A13: 734939 | B13: 501.9 | C13: =VLOOKUP(A13,name_ID!$A$2:$B$401,2,FALSE) -> B4I_2025_NY_5004
... A83: 734841 | B83: 547.2 | C83: =VLOOKUP(A83,name_ID!$A$2:$B$401,2,FALSE) -> B4I_2025_NY_5298
A84: 734951 | C84: =VLOOKUP(A84,name_ID!$A$2:$B$401,2,FALSE) -> B4I_2025_NY_5206
A85: 734781 | B85: 837.8 | C85: =VLOOKUP(A85,name_ID!$A$2:$B$401,2,FALSE) -> B4I_2025_NY_5174
A86: 734818 | B86: 789.8 | C86: =VLOOKUP(A86,name_ID!$A$2:$B$401,2,FALSE) -> B4I_2025_NY_5248
A87: 734820 | B87: 464.1 | C87: =VLOOKUP(A87,name_ID!$A$2:$B$401,2,FALSE) -> B4I_2025_NY_5077
A88: 734842 | B88: 585.5 | C88: =VLOOKUP(A88,name_ID!$A$2:$B$401,2,FALSE) -> B4I_2025_NY_5323
A89: 734759 | B89: 608.6 | C89: =VLOOKUP(A89,name_ID!$A$2:$B$401,2,FALSE) -> B4I_2025_NY_5122
A90: 735009 | B90: 533.9 | C90: =VLOOKUP(A90,name_ID!$A$2:$B$401,2,FALSE) -> B4I_2025_NY_5222
A91: 734999 | B91: 732 | C91: =VLOOKUP(A91,name_ID!$A$2:$B$401,2,FALSE) -> B4I_2025_NY_5242
A92: 735062 | B92: 682 | C92: =VLOOKUP(A92,name_ID!$A$2:$B$401,2,FALSE) -> B4I_2025_NY_5255
A93: 734813 | B93: 477.1 | C93: =VLOOKUP(A93,name_ID!$A$2:$B$401,2,FALSE) -> B4I_2025_NY_5155
A94: 734979 | B94: 546.5 | C94: =VLOOKUP(A94,name_ID!$A$2:$B$401,2,FALSE) -> B4I_2025_NY_5093
A95: 735089 | B95: 639.8 | C95: =VLOOKUP(A95,name_ID!$A$2:$B$401,2,FALSE) -> B4I_2025_NY_5158
A96: 734824 | B96: 653.5 | C96: =VLOOKUP(A96,name_ID!$A$2:$B$401,2,FALSE) -> B4I_2025_NY_5262
... A225: 734961 | B225: 631.4 | C225: =VLOOKUP(A225,name_ID!$A$2:$B$401,2,FALSE) -> B4I_2025_NY_5226
B226: 47 | C226: B4I_2025_NY_5017
B227: 63.7 | C227: B4I_2025_NY_5028
B228: 54.9 | C228: B4I_2025_NY_5107
B229: 484.5 | C229: B4I_2025_NY_5179
C230: B4I_2025_NY_5245

Sheet pea_1
A1: ID | B1: Pea Grain Weight - g|CO_xxx:0003006 | C1: 100 seed weight | D1: Pea Thousand Grain Weight - g|CO_xxx:0003017 | E1: observationUnitName
A2: 734739 | B2: 493.4 | C2: 23.37 | D2: =C2*10 -> 233.7 | E2: =VLOOKUP($A2,name_ID!$A$2:$B$401,2,FALSE) -> B4I_2025_NY_5009
A3: 734918 | B3: 466.3 | C3: 22.05 | D3: =C3*10 -> 220.5 | E3: =VLOOKUP($A3,name_ID!$A$2:$B$401,2,FALSE) -> B4I_2025_NY_5003
A4: 735052 | B4: 276.7 | C4: 22.73 | D4: =C4*10 -> 227.3 | E4: =VLOOKUP($A4,name_ID!$A$2:$B$401,2,FALSE) -> B4I_2025_NY_5243
A5: 735022 | B5: 469.4 | C5: 18.99 | D5: =C5*10 -> 189.9 | E5: =VLOOKUP($A5,name_ID!$A$2:$B$401,2,FALSE) -> B4I_2025_NY_5046
A6: 734844 | B6: 428.9 | C6: 21.88 | D6: =C6*10 -> 218.8 | E6: =VLOOKUP($A6,name_ID!$A$2:$B$401,2,FALSE) -> B4I_2025_NY_5105
A7: 734861 | B7: 562.9 | C7: 21.37 | D7: =C7*10 -> 213.7 | E7: =VLOOKUP($A7,name_ID!$A$2:$B$401,2,FALSE) -> B4I_2025_NY_5153
A8: 735037 | B8: 382.8 | C8: 21.48 | D8: =C8*10 -> 214.8 | E8: =VLOOKUP($A8,name_ID!$A$2:$B$401,2,FALSE) -> B4I_2025_NY_5348
A9: 734718 | B9: 575.5 | C9: 20.42 | D9: =C9*10 -> 204.2 | E9: =VLOOKUP($A9,name_ID!$A$2:$B$401,2,FALSE) -> B4I_2025_NY_5007
A10: 734841 | B10: 366.9 | C10: 22.55 | D10: =C10*10 -> 225.5 | E10: =VLOOKUP($A10,name_ID!$A$2:$B$401,2,FALSE) -> B4I_2025_NY_5298
A11: 735096 | B11: 316.1 | C11: 19.42 | D11: =C11*10 -> 194.2 | E11: =VLOOKUP($A11,name_ID!$A$2:$B$401,2,FALSE) -> B4I_2025_NY_5006
A12: 734930 | B12: 322.5 | C12: 19.62 | D12: =C12*10 -> 196.2 | E12: =VLOOKUP($A12,name_ID!$A$2:$B$401,2,FALSE) -> B4I_2025_NY_5095
A13: 734838 | B13: 374.5 | C13: 20.31 | D13: =C13*10 -> 203.1 | E13: =VLOOKUP($A13,name_ID!$A$2:$B$401,2,FALSE) -> B4I_2025_NY_5227
... A268: 735009 | B268: 507 | C268: 19.11 | D268: =C268*10 -> 191.1 | E268: =VLOOKUP($A268,name_ID!$A$2:$B$401,2,FALSE) -> B4I_2025_NY_5222
A269: 734951 | E269: =VLOOKUP($A269,name_ID!$A$2:$B$401,2,FALSE) -> B4I_2025_NY_5206
A270: 735020 | B270: 484.7 | C270: 22.83 | D270: =C270*10 -> 228.3 | E270: =VLOOKUP($A270,name_ID!$A$2:$B$401,2,FALSE) -> B4I_2025_NY_5328
A271: 734819 | B271: 444.7 | C271: 17.95 | D271: =C271*10 -> 179.5 | E271: =VLOOKUP($A271,name_ID!$A$2:$B$401,2,FALSE) -> B4I_2025_NY_5344
A272: 734895 | B272: 536 | C272: 19.28 | D272: =C272*10 -> 192.8 | E272: =VLOOKUP($A272,name_ID!$A$2:$B$401,2,FALSE) -> B4I_2025_NY_5154
A273: 735024 | B273: 353.4 | C273: 16.19 | D273: =C273*10 -> 161.9 | E273: =VLOOKUP($A273,name_ID!$A$2:$B$401,2,FALSE) -> B4I_2025_NY_5379
A274: 735045 | B274: 350.8 | C274: 19.22 | D274: =C274*10 -> 192.2 | E274: =VLOOKUP($A274,name_ID!$A$2:$B$401,2,FALSE) -> B4I_2025_NY_5398
A275: 735000 | B275: 500.3 | C275: 19.68 | D275: =C275*10 -> 196.8 | E275: =VLOOKUP($A275,name_ID!$A$2:$B$401,2,FALSE) -> B4I_2025_NY_5177
A276: 734803 | B276: 351 | C276: 21.53 | D276: =C276*10 -> 215.3 | E276: =VLOOKUP($A276,name_ID!$A$2:$B$401,2,FALSE) -> B4I_2025_NY_5322
A277: 735069 | B277: 515.2 | C277: 19.52 | D277: =C277*10 -> 195.2 | E277: =VLOOKUP($A277,name_ID!$A$2:$B$401,2,FALSE) -> B4I_2025_NY_5056
A278: 734797 | B278: 336.9 | C278: 20.25 | D278: =C278*10 -> 202.5 | E278: =VLOOKUP($A278,name_ID!$A$2:$B$401,2,FALSE) -> B4I_2025_NY_5173
A279: 735089 | B279: 335.9 | C279: 21.83 | D279: =C279*10 -> 218.3 | E279: =VLOOKUP($A279,name_ID!$A$2:$B$401,2,FALSE) -> B4I_2025_NY_5158
A280: 735102 | B280: 458.4 | C280: 21.88 | D280: =C280*10 -> 218.8 | E280: =VLOOKUP($A280,name_ID!$A$2:$B$401,2,FALSE) -> B4I_2025_NY_5357
A281: 734821 | B281: 648.2 | C281: 18.94 | D281: =C281*10 -> 189.4 | E281: =VLOOKUP($A281,name_ID!$A$2:$B$401,2,FALSE) -> B4I_2025_NY_5063
A282: 735087 | B282: 379.3 | C282: 20.77 | D282: =C282*10 -> 207.7 | E282: =VLOOKUP($A282,name_ID!$A$2:$B$401,2,FALSE) -> B4I_2025_NY_5307

Sheet B4I Oat Harvest Weights 10_1_25
A1: ID number | B1: Grain weight - g|CO_350:0005123 | C1: Test Weight (g/110mL) | D1: observationUnitName | E1: Test weight - g/L|CO_350:0000259
A2: 734893 | B2: 658.5 | C2: 48.56 | D2: =VLOOKUP($A2,name_ID!$A$2:$B$401,2,FALSE) -> B4I_2025_NY_5089 | E2: =C2*9.090909 -> 441.45454
A3: 735100 | B3: 606.9 | C3: 46.67 | D3: =VLOOKUP($A3,name_ID!$A$2:$B$401,2,FALSE) -> B4I_2025_NY_5259 | E3: =C3*9.090909 -> 424.27272
A4: 735070 | B4: 780.8 | C4: 46.89 | D4: =VLOOKUP($A4,name_ID!$A$2:$B$401,2,FALSE) -> B4I_2025_NY_5109 | E4: =C4*9.090909 -> 426.27272
A5: 735004 | B5: 700.2 | C5: 47.74 | D5: =VLOOKUP($A5,name_ID!$A$2:$B$401,2,FALSE) -> B4I_2025_NY_5076 | E5: =C5*9.090909 -> 434
A6: 734853 | B6: 640.5 | C6: 44.67 | D6: =VLOOKUP($A6,name_ID!$A$2:$B$401,2,FALSE) -> B4I_2025_NY_5280 | E6: =C6*9.090909 -> 406.09091
A7: 735026 | B7: 450.5 | C7: 36.71 | D7: =VLOOKUP($A7,name_ID!$A$2:$B$401,2,FALSE) -> B4I_2025_NY_5073 | E7: =C7*9.090909 -> 333.72727
A8: 735003 | B8: 725.3 | C8: 46.96 | D8: =VLOOKUP($A8,name_ID!$A$2:$B$401,2,FALSE) -> B4I_2025_NY_5329 | E8: =C8*9.090909 -> 426.90909
A9: 734839 | B9: 609.3 | C9: 45.66 | D9: =VLOOKUP($A9,name_ID!$A$2:$B$401,2,FALSE) -> B4I_2025_NY_5144 | E9: =C9*9.090909 -> 415.0909
A10: 735038 | B10: 709.4 | C10: 45.27 | D10: =VLOOKUP($A10,name_ID!$A$2:$B$401,2,FALSE) -> B4I_2025_NY_5244 | E10: =C10*9.090909 -> 411.54545
A11: 734977 | B11: 600.4 | C11: 48.19 | D11: =VLOOKUP($A11,name_ID!$A$2:$B$401,2,FALSE) -> B4I_2025_NY_5101 | E11: =C11*9.090909 -> 438.0909
A12: 734783 | B12: 525.5 | C12: 43.57 | D12: =VLOOKUP($A12,name_ID!$A$2:$B$401,2,FALSE) -> B4I_2025_NY_5342 | E12: =C12*9.090909 -> 396.09091
A13: 734774 | B13: 329 | C13: 41.48 | D13: =VLOOKUP($A13,name_ID!$A$2:$B$401,2,FALSE) -> B4I_2025_NY_5196 | E13: =C13*9.090909 -> 377.09091
... A151: 734891 | B151: 536 | C151: 48.28 | D151: =VLOOKUP($A151,name_ID!$A$2:$B$401,2,FALSE) -> B4I_2025_NY_5091 | E151: =C151*9.090909 -> 438.90909

Sheet B4I Pea Harvest Weights 10_2_25
A1: ID number | B1: Pea Grain Weight - g|CO_xxx:0003006 | C1: Test Weight (g/110mL) | D1: observationUnitName | E1: Pea Test Weight - g/L|CO_xxx:0003016 | F1: observationUnitName
A2: 734905 | B2: 60.1 | C2: na | D2: =VLOOKUP($A2,name_ID!$A$2:$B$401,2,FALSE) -> B4I_2025_NY_5133 | E2: =C2*9.090909 -> #VALUE! | F2: =VLOOKUP($A2,name_ID!$A$2:$B$401,2,FALSE) -> B4I_2025_NY_5133
A3: 734953 | B3: 380.8 | C3: 103.87 | D3: =VLOOKUP($A3,name_ID!$A$2:$B$401,2,FALSE) -> B4I_2025_NY_5283 | E3: =C3*9.090909 -> 944.27272 | F3: =VLOOKUP($A3,name_ID!$A$2:$B$401,2,FALSE) -> B4I_2025_NY_5283
A4: 734832 | B4: 16.5 | C4: na | D4: =VLOOKUP($A4,name_ID!$A$2:$B$401,2,FALSE) -> B4I_2025_NY_5017 | E4: =C4*9.090909 -> #VALUE! | F4: =VLOOKUP($A4,name_ID!$A$2:$B$401,2,FALSE) -> B4I_2025_NY_5017
A5: 734940 | B5: 251.6 | C5: 99.35 | D5: =VLOOKUP($A5,name_ID!$A$2:$B$401,2,FALSE) -> B4I_2025_NY_5119 | E5: =C5*9.090909 -> 903.18181 | F5: =VLOOKUP($A5,name_ID!$A$2:$B$401,2,FALSE) -> B4I_2025_NY_5119
A6: 735105 | B6: 143.3 | C6: 103.51 | D6: =VLOOKUP($A6,name_ID!$A$2:$B$401,2,FALSE) -> B4I_2025_NY_5137 | E6: =C6*9.090909 -> 940.99999 | F6: =VLOOKUP($A6,name_ID!$A$2:$B$401,2,FALSE) -> B4I_2025_NY_5137
A7: 734747 | B7: 311 | C7: 97.78 | D7: =VLOOKUP($A7,name_ID!$A$2:$B$401,2,FALSE) -> B4I_2025_NY_5291 | E7: =C7*9.090909 -> 888.90908 | F7: =VLOOKUP($A7,name_ID!$A$2:$B$401,2,FALSE) -> B4I_2025_NY_5291
A8: 734949 | B8: 152.1 | C8: 100.85 | D8: =VLOOKUP($A8,name_ID!$A$2:$B$401,2,FALSE) -> B4I_2025_NY_5165 | E8: =C8*9.090909 -> 916.81817 | F8: =VLOOKUP($A8,name_ID!$A$2:$B$401,2,FALSE) -> B4I_2025_NY_5165
A9: 734877 | B9: 100.9 | C9: 100.96 | D9: =VLOOKUP($A9,name_ID!$A$2:$B$401,2,FALSE) -> B4I_2025_NY_5134 | E9: =C9*9.090909 -> 917.81817 | F9: =VLOOKUP($A9,name_ID!$A$2:$B$401,2,FALSE) -> B4I_2025_NY_5134
A10: 734985 | B10: 117.2 | C10: 101.56 | D10: =VLOOKUP($A10,name_ID!$A$2:$B$401,2,FALSE) -> B4I_2025_NY_5118 | E10: =C10*9.090909 -> 923.27272 | F10: =VLOOKUP($A10,name_ID!$A$2:$B$401,2,FALSE) -> B4I_2025_NY_5118
A11: 734777 | B11: 265.8 | C11: 99.14 | D11: =VLOOKUP($A11,name_ID!$A$2:$B$401,2,FALSE) -> B4I_2025_NY_5392 | E11: =C11*9.090909 -> 901.27272 | F11: =VLOOKUP($A11,name_ID!$A$2:$B$401,2,FALSE) -> B4I_2025_NY_5392
A12: 734723 | B12: 332.2 | C12: 98.16 | D12: =VLOOKUP($A12,name_ID!$A$2:$B$401,2,FALSE) -> B4I_2025_NY_5265 | E12: =C12*9.090909 -> 892.36363 | F12: =VLOOKUP($A12,name_ID!$A$2:$B$401,2,FALSE) -> B4I_2025_NY_5265
A13: 734911 | B13: 161.7 | C13: 101.06 | D13: =VLOOKUP($A13,name_ID!$A$2:$B$401,2,FALSE) -> B4I_2025_NY_5187 | E13: =C13*9.090909 -> 918.72726 | F13: =VLOOKUP($A13,name_ID!$A$2:$B$401,2,FALSE) -> B4I_2025_NY_5187
A14: 734941 | B14: 146.1 | C14: 101.65 | D14: =VLOOKUP($A14,name_ID!$A$2:$B$401,2,FALSE) -> B4I_2025_NY_5121 | E14: =C14*9.090909 -> 924.0909 | F14: =VLOOKUP($A14,name_ID!$A$2:$B$401,2,FALSE) -> B4I_2025_NY_5121
A15: 734928 | B15: 171.8 | C15: 96.6 | D15: =VLOOKUP($A15,name_ID!$A$2:$B$401,2,FALSE) -> B4I_2025_NY_5284 | E15: =C15*9.090909 -> 878.18181 | F15: =VLOOKUP($A15,name_ID!$A$2:$B$401,2,FALSE) -> B4I_2025_NY_5284
A16: 735051 | B16: 269.1 | C16: 97.33 | D16: =VLOOKUP($A16,name_ID!$A$2:$B$401,2,FALSE) -> B4I_2025_NY_5014 | E16: =C16*9.090909 -> 884.81817 | F16: =VLOOKUP($A16,name_ID!$A$2:$B$401,2,FALSE) -> B4I_2025_NY_5014
... A33: 734878 | B33: 336.4 | C33: 104.89 | D33: =VLOOKUP($A33,name_ID!$A$2:$B$401,2,FALSE) -> B4I_2025_NY_5065 | E33: =C33*9.090909 -> 953.54545 | F33: =VLOOKUP($A33,name_ID!$A$2:$B$401,2,FALSE) -> B4I_2025_NY_5065
A34: 734970 | B34: 19.1 | C34: na | D34: =VLOOKUP($A34,name_ID!$A$2:$B$401,2,FALSE) -> B4I_2025_NY_5267 | E34: =C34*9.090909 -> #VALUE! | F34: =VLOOKUP($A34,name_ID!$A$2:$B$401,2,FALSE) -> B4I_2025_NY_5267
A35: 735013 | B35: 91.7 | C35: na | D35: =VLOOKUP($A35,name_ID!$A$2:$B$401,2,FALSE) -> B4I_2025_NY_5117 | E35: =C35*9.090909 -> #VALUE! | F35: =VLOOKUP($A35,name_ID!$A$2:$B$401,2,FALSE) -> B4I_2025_NY_5117
A36: 734826 | B36: 228.5 | C36: 99.55 | D36: =VLOOKUP($A36,name_ID!$A$2:$B$401,2,FALSE) -> B4I_2025_NY_5049 | E36: =C36*9.090909 -> 904.99999 | F36: =VLOOKUP($A36,name_ID!$A$2:$B$401,2,FALSE) -> B4I_2025_NY_5049
A37: 734837 | B37: 241.8 | C37: 98.62 | D37: =VLOOKUP($A37,name_ID!$A$2:$B$401,2,FALSE) -> B4I_2025_NY_5112 | E37: =C37*9.090909 -> 896.54545 | F37: =VLOOKUP($A37,name_ID!$A$2:$B$401,2,FALSE) -> B4I_2025_NY_5112
A38: 734876 | B38: 317.9 | C38: 100.57 | D38: =VLOOKUP($A38,name_ID!$A$2:$B$401,2,FALSE) -> B4I_2025_NY_5041 | E38: =C38*9.090909 -> 914.27272 | F38: =VLOOKUP($A38,name_ID!$A$2:$B$401,2,FALSE) -> B4I_2025_NY_5041
A39: 735062 | B39: 319.4 | C39: 100.79 | D39: =VLOOKUP($A39,name_ID!$A$2:$B$401,2,FALSE) -> B4I_2025_NY_5255 | E39: =C39*9.090909 -> 916.27272 | F39: =VLOOKUP($A39,name_ID!$A$2:$B$401,2,FALSE) -> B4I_2025_NY_5255
A40: 734987 | B40: 179.2 | C40: 101.17 | D40: =VLOOKUP($A40,name_ID!$A$2:$B$401,2,FALSE) -> B4I_2025_NY_5100 | E40: =C40*9.090909 -> 919.72726 | F40: =VLOOKUP($A40,name_ID!$A$2:$B$401,2,FALSE) -> B4I_2025_NY_5100
A41: 734858 | B41: 258.6 | C41: 102.04 | D41: =VLOOKUP($A41,name_ID!$A$2:$B$401,2,FALSE) -> B4I_2025_NY_5064 | E41: =C41*9.090909 -> 927.63635 | F41: =VLOOKUP($A41,name_ID!$A$2:$B$401,2,FALSE) -> B4I_2025_NY_5064
A42: 734770 | B42: 200.4 | C42: 100.34 | D42: =VLOOKUP($A42,name_ID!$A$2:$B$401,2,FALSE) -> B4I_2025_NY_5062 | E42: =C42*9.090909 -> 912.18181 | F42: =VLOOKUP($A42,name_ID!$A$2:$B$401,2,FALSE) -> B4I_2025_NY_5062
A43: 734749 | B43: 149.8 | C43: 104.53 | D43: =VLOOKUP($A43,name_ID!$A$2:$B$401,2,FALSE) -> B4I_2025_NY_5175 | E43: =C43*9.090909 -> 950.27272 | F43: =VLOOKUP($A43,name_ID!$A$2:$B$401,2,FALSE) -> B4I_2025_NY_5175
A44: 734939 | B44: 287.5 | C44: 103.41 | D44: =VLOOKUP($A44,name_ID!$A$2:$B$401,2,FALSE) -> B4I_2025_NY_5004 | E44: =C44*9.090909 -> 940.0909 | F44: =VLOOKUP($A44,name_ID!$A$2:$B$401,2,FALSE) -> B4I_2025_NY_5004
A45: 734974 | B45: 254.5 | C45: 103.17 | D45: =VLOOKUP($A45,name_ID!$A$2:$B$401,2,FALSE) -> B4I_2025_NY_5351 | E45: =C45*9.090909 -> 937.90908 | F45: =VLOOKUP($A45,name_ID!$A$2:$B$401,2,FALSE) -> B4I_2025_NY_5351
A46: 734773 | B46: 241.1 | C46: 98.5 | D46: =VLOOKUP($A46,name_ID!$A$2:$B$401,2,FALSE) -> B4I_2025_NY_5097 | E46: =C46*9.090909 -> 895.45454 | F46: =VLOOKUP($A46,name_ID!$A$2:$B$401,2,FALSE) -> B4I_2025_NY_5097
A47: 735050 | B47: 262.8 | C47: 103.12 | D47: =VLOOKUP($A47,name_ID!$A$2:$B$401,2,FALSE) -> B4I_2025_NY_5068 | E47: =C47*9.090909 -> 937.45454 | F47: =VLOOKUP($A47,name_ID!$A$2:$B$401,2,FALSE) -> B4I_2025_NY_5068
... A50: 734855 | B50: 162.4 | C50: 104.62 | D50: =VLOOKUP($A50,name_ID!$A$2:$B$401,2,FALSE) -> B4I_2025_NY_5135 | E50: =C50*9.090909 -> 951.0909 | F50: =VLOOKUP($A50,name_ID!$A$2:$B$401,2,FALSE) -> B4I_2025_NY_5135
A51: 734732 | B51: 69.5 | C51: na | D51: =VLOOKUP($A51,name_ID!$A$2:$B$401,2,FALSE) -> B4I_2025_NY_5136 | E51: =C51*9.090909 -> #VALUE! | F51: =VLOOKUP($A51,name_ID!$A$2:$B$401,2,FALSE) -> B4I_2025_NY_5136
A52: 734926 | B52: 268.9 | C52: 99.53 | D52: =VLOOKUP($A52,name_ID!$A$2:$B$401,2,FALSE) -> B4I_2025_NY_5319 | E52: =C52*9.090909 -> 904.81817 | F52: =VLOOKUP($A52,name_ID!$A$2:$B$401,2,FALSE) -> B4I_2025_NY_5319
A53: 734971 | B53: 207.8 | C53: 99.54 | D53: =VLOOKUP($A53,name_ID!$A$2:$B$401,2,FALSE) -> B4I_2025_NY_5150 | E53: =C53*9.090909 -> 904.90908 | F53: =VLOOKUP($A53,name_ID!$A$2:$B$401,2,FALSE) -> B4I_2025_NY_5150
A54: 734782 | B54: 5.9 | C54: na | D54: =VLOOKUP($A54,name_ID!$A$2:$B$401,2,FALSE) -> B4I_2025_NY_5028 | E54: =C54*9.090909 -> #VALUE! | F54: =VLOOKUP($A54,name_ID!$A$2:$B$401,2,FALSE) -> B4I_2025_NY_5028
A55: 734818 | B55: 57.8 | C55: na | D55: =VLOOKUP($A55,name_ID!$A$2:$B$401,2,FALSE) -> B4I_2025_NY_5248 | E55: =C55*9.090909 -> #VALUE! | F55: =VLOOKUP($A55,name_ID!$A$2:$B$401,2,FALSE) -> B4I_2025_NY_5248
A56: 734929 | B56: 96.9 | C56: 96.97 | D56: =VLOOKUP($A56,name_ID!$A$2:$B$401,2,FALSE) -> B4I_2025_NY_5120 | E56: =C56*9.090909 -> 881.54545 | F56: =VLOOKUP($A56,name_ID!$A$2:$B$401,2,FALSE) -> B4I_2025_NY_5120
A57: 735006 | B57: 130.7 | C57: 104.32 | D57: =VLOOKUP($A57,name_ID!$A$2:$B$401,2,FALSE) -> B4I_2025_NY_5149 | E57: =C57*9.090909 -> 948.36363 | F57: =VLOOKUP($A57,name_ID!$A$2:$B$401,2,FALSE) -> B4I_2025_NY_5149
A58: 735103 | B58: 0 | C58: na | D58: =VLOOKUP($A58,name_ID!$A$2:$B$401,2,FALSE) -> B4I_2025_NY_5245 | E58: =C58*9.090909 -> #VALUE! | F58: =VLOOKUP($A58,name_ID!$A$2:$B$401,2,FALSE) -> B4I_2025_NY_5245
...

Sheet oat_2_1000
A1: ID | B1: un-tared bag+grain weights (g) | C1: Grain weight - g|CO_350:0005123 | D1: hundred_seed_weight (g) | E1: Thousand grain weight - g|CO_350:0000251 | F1: observationUnitName
A2: 734739 | D2: 1.98 | E2: =D2*10 -> 19.8 | F2: =VLOOKUP($A2,name_ID!$A$2:$B$401,2,FALSE) -> B4I_2025_NY_5009
A3: 734946 | D3: 2.18 | E3: =D3*10 -> 21.8 | F3: =VLOOKUP($A3,name_ID!$A$2:$B$401,2,FALSE) -> B4I_2025_NY_5139
A4: 734835 | D4: 2.33 | E4: =D4*10 -> 23.3 | F4: =VLOOKUP($A4,name_ID!$A$2:$B$401,2,FALSE) -> B4I_2025_NY_5031
A5: 734751 | D5: 3.08 | E5: =D5*10 -> 30.8 | F5: =VLOOKUP($A5,name_ID!$A$2:$B$401,2,FALSE) -> B4I_2025_NY_5383
A6: 734961 | D6: 2.86 | E6: =D6*10 -> 28.6 | F6: =VLOOKUP($A6,name_ID!$A$2:$B$401,2,FALSE) -> B4I_2025_NY_5226
A7: 734771 | D7: 2.92 | E7: =D7*10 -> 29.2 | F7: =VLOOKUP($A7,name_ID!$A$2:$B$401,2,FALSE) -> B4I_2025_NY_5168
A8: 734969 | D8: 2.18 | E8: =D8*10 -> 21.8 | F8: =VLOOKUP($A8,name_ID!$A$2:$B$401,2,FALSE) -> B4I_2025_NY_5317
A9: 734877 | D9: 2.01 | E9: =D9*10 -> 20.1 | F9: =VLOOKUP($A9,name_ID!$A$2:$B$401,2,FALSE) -> B4I_2025_NY_5134
A10: 734993 | D10: 3.27 | E10: =D10*10 -> 32.7 | F10: =VLOOKUP($A10,name_ID!$A$2:$B$401,2,FALSE) -> B4I_2025_NY_5268
A11: 735067 | D11: 2.29 | E11: =D11*10 -> 22.9 | F11: =VLOOKUP($A11,name_ID!$A$2:$B$401,2,FALSE) -> B4I_2025_NY_5032
A12: 735013 | D12: 2.54 | E12: =D12*10 -> 25.4 | F12: =VLOOKUP($A12,name_ID!$A$2:$B$401,2,FALSE) -> B4I_2025_NY_5117
A13: 734715 | D13: 2.13 | E13: =D13*10 -> 21.3 | F13: =VLOOKUP($A13,name_ID!$A$2:$B$401,2,FALSE) -> B4I_2025_NY_5375
... A205: 734848 | D205: 2.75 | E205: =D205*10 -> 27.5 | F205: =VLOOKUP($A205,name_ID!$A$2:$B$401,2,FALSE) -> B4I_2025_NY_5001
A206: 734762 | B206: 856.3 | C206: =B206-22.92 -> 833.38 | D206: 2.49 | E206: =D206*10 -> 24.9 | F206: =VLOOKUP($A206,name_ID!$A$2:$B$401,2,FALSE) -> B4I_2025_NY_5217
A207: 734747 | B207: 804.3 | C207: =B207-22.92 -> 781.38 | D207: 2.48 | E207: =D207*10 -> 24.8 | F207: =VLOOKUP($A207,name_ID!$A$2:$B$401,2,FALSE) -> B4I_2025_NY_5291
A208: 734721 | B208: 740.5 | C208: =B208-22.92 -> 717.58 | D208: 2.34 | E208: =D208*10 -> 23.4 | F208: =VLOOKUP($A208,name_ID!$A$2:$B$401,2,FALSE) -> B4I_2025_NY_5315 | G208: hand written lable (5315)
A209: 734942 | B209: 663.5 | C209: =B209-22.92 -> 640.58 | D209: 2.23 | E209: =D209*10 -> 22.3 | F209: =VLOOKUP($A209,name_ID!$A$2:$B$401,2,FALSE) -> B4I_2025_NY_5236
A210: 734919 | B210: 916.8 | C210: =B210-22.92 -> 893.88 | D210: 2.63 | E210: =D210*10 -> 26.3 | F210: =VLOOKUP($A210,name_ID!$A$2:$B$401,2,FALSE) -> B4I_2025_NY_5191
A211: 735064 | B211: 776.7 | C211: =B211-22.92 -> 753.78 | D211: 2.14 | E211: =D211*10 -> 21.4 | F211: =VLOOKUP($A211,name_ID!$A$2:$B$401,2,FALSE) -> B4I_2025_NY_5260
A212: 735034 | B212: 726.6 | C212: =B212-22.92 -> 703.68 | D212: 2.57 | E212: =D212*10 -> 25.7 | F212: =VLOOKUP($A212,name_ID!$A$2:$B$401,2,FALSE) -> B4I_2025_NY_5212
A213: 734949 | B213: 910.1 | C213: =B213-22.92 -> 887.18 | D213: 2.47 | E213: =D213*10 -> 24.7 | F213: =VLOOKUP($A213,name_ID!$A$2:$B$401,2,FALSE) -> B4I_2025_NY_5165
A214: 735051 | B214: 691.8 | C214: =B214-22.92 -> 668.88 | D214: 1.73 | E214: =D214*10 -> 17.3 | F214: =VLOOKUP($A214,name_ID!$A$2:$B$401,2,FALSE) -> B4I_2025_NY_5014
A215: 734947 | B215: 802.1 | C215: =B215-22.92 -> 779.18 | D215: 2.43 | E215: =D215*10 -> 24.3 | F215: =VLOOKUP($A215,name_ID!$A$2:$B$401,2,FALSE) -> B4I_2025_NY_5141
A216: 734954 | B216: 859.6 | C216: =B216-22.92 -> 836.68 | D216: 2.2 | E216: =D216*10 -> 22 | F216: =VLOOKUP($A216,name_ID!$A$2:$B$401,2,FALSE) -> B4I_2025_NY_5190
A217: 735082 | B217: 610.9 | C217: =B217-22.92 -> 587.98 | D217: 2.04 | E217: =D217*10 -> 20.4 | F217: =VLOOKUP($A217,name_ID!$A$2:$B$401,2,FALSE) -> B4I_2025_NY_5254
A218: 735085 | B218: 686.6 | C218: =B218-22.92 -> 663.68 | D218: 2.43 | E218: =D218*10 -> 24.3 | F218: =VLOOKUP($A218,name_ID!$A$2:$B$401,2,FALSE) -> B4I_2025_NY_5138
A219: 734727 | B219: 528 | C219: =B219-22.92 -> 505.08 | D219: 2.36 | E219: =D219*10 -> 23.6 | F219: =VLOOKUP($A219,name_ID!$A$2:$B$401,2,FALSE) -> B4I_2025_NY_5037
A220: 735061 | B220: 526.1 | C220: =B220-22.92 -> 503.18 | D220: 1.98 | E220: =D220*10 -> 19.8 | F220: =VLOOKUP($A220,name_ID!$A$2:$B$401,2,FALSE) -> B4I_2025_NY_5347
... A245: 735042 | B245: 630.4 | C245: =B245-22.92 -> 607.48 | D245: 2.26 | E245: =D245*10 -> 22.6 | F245: =VLOOKUP($A245,name_ID!$A$2:$B$401,2,FALSE) -> B4I_2025_NY_5085

Sheet oat_3_1000
A1: ID | B1: Thousand grain weight - g|CO_350:0000251 | C1: observationUnitName
A2: 734921 | B2: 19.4 | C2: =VLOOKUP($A2,name_ID!$A$2:$B$401,2,FALSE) -> B4I_2025_NY_5054
A3: 734837 | B3: 17.9 | C3: =VLOOKUP($A3,name_ID!$A$2:$B$401,2,FALSE) -> B4I_2025_NY_5112
A4: 734864 | B4: 22.1 | C4: =VLOOKUP($A4,name_ID!$A$2:$B$401,2,FALSE) -> B4I_2025_NY_5104
A5: 735074 | B5: 19.3 | C5: =VLOOKUP($A5,name_ID!$A$2:$B$401,2,FALSE) -> B4I_2025_NY_5084
A6: 734944 | B6: 20 | C6: =VLOOKUP($A6,name_ID!$A$2:$B$401,2,FALSE) -> B4I_2025_NY_5059
A7: 734987 | B7: 16.7 | C7: =VLOOKUP($A7,name_ID!$A$2:$B$401,2,FALSE) -> B4I_2025_NY_5100
A8: 734798 | B8: 15.6 | C8: =VLOOKUP($A8,name_ID!$A$2:$B$401,2,FALSE) -> B4I_2025_NY_5098
A9: 734716 | B9: 17.7 | C9: =VLOOKUP($A9,name_ID!$A$2:$B$401,2,FALSE) -> B4I_2025_NY_5058
A10: 734972 | B10: 17.8 | C10: =VLOOKUP($A10,name_ID!$A$2:$B$401,2,FALSE) -> B4I_2025_NY_5005
A11: 735022 | B11: 18.5 | C11: =VLOOKUP($A11,name_ID!$A$2:$B$401,2,FALSE) -> B4I_2025_NY_5046
A12: 734863 | B12: 17.2 | C12: =VLOOKUP($A12,name_ID!$A$2:$B$401,2,FALSE) -> B4I_2025_NY_5088
A13: 735080 | B13: 19.6 | C13: =VLOOKUP($A13,name_ID!$A$2:$B$401,2,FALSE) -> B4I_2025_NY_5358
... A149: 734900 | B149: 22.7 | C149: =VLOOKUP($A149,name_ID!$A$2:$B$401,2,FALSE) -> B4I_2025_NY_5020

Sheet oat moisture
A1: SampleId | B1: Grain moisture content - percent|CO_350:0000536 | C1: Product | D1: DateTime | E1: Error | F1: observationUnitName
A2: 734992 | B2: 9.5195147 | C2: Oats | D2: 45909.467 | E2: NO_ERROR | F2: =VLOOKUP($A2,name_ID!$A$2:$B$401,2,FALSE) -> B4I_2025_NY_5299
A3: 735007 | B3: 9.6582242 | C3: Oats | D3: 45909.47 | E3: NO_ERROR | F3: =VLOOKUP($A3,name_ID!$A$2:$B$401,2,FALSE) -> B4I_2025_NY_5151
A4: 734844 | B4: 9.947943 | C4: Oats | D4: 45909.471 | E4: SAMPLE_WEIGHT_TOO_LOW | F4: =VLOOKUP($A4,name_ID!$A$2:$B$401,2,FALSE) -> B4I_2025_NY_5105
A5: 734845 | B5: 9.8784069 | C5: Oats | D5: 45909.472 | E5: SAMPLE_WEIGHT_TOO_LOW | F5: =VLOOKUP($A5,name_ID!$A$2:$B$401,2,FALSE) -> B4I_2025_NY_5172
A6: 734737 | B6: 9.5675316 | C6: Oats | D6: 45909.472 | E6: NO_ERROR | F6: =VLOOKUP($A6,name_ID!$A$2:$B$401,2,FALSE) -> B4I_2025_NY_5156
A7: 734945 | B7: 10.317108 | C7: Oats | D7: 45909.473 | E7: SAMPLE_WEIGHT_TOO_LOW | F7: =VLOOKUP($A7,name_ID!$A$2:$B$401,2,FALSE) -> B4I_2025_NY_5045
A8: 734861 | B8: 9.5522793 | C8: Oats | D8: 45909.474 | E8: NO_ERROR | F8: =VLOOKUP($A8,name_ID!$A$2:$B$401,2,FALSE) -> B4I_2025_NY_5153
A9: 734853 | B9: 9.7414195 | C9: Oats | D9: 45909.474 | E9: SAMPLE_WEIGHT_TOO_LOW | F9: =VLOOKUP($A9,name_ID!$A$2:$B$401,2,FALSE) -> B4I_2025_NY_5280
A10: 735096 | B10: 9.5661494 | C10: Oats | D10: 45909.475 | E10: NO_ERROR | F10: =VLOOKUP($A10,name_ID!$A$2:$B$401,2,FALSE) -> B4I_2025_NY_5006
A11: 734929 | B11: 9.5262912 | C11: Oats | D11: 45909.477 | E11: NO_ERROR | F11: =VLOOKUP($A11,name_ID!$A$2:$B$401,2,FALSE) -> B4I_2025_NY_5120
A12: 735026 | B12: 9.2056789 | C12: Oats | D12: 45909.478 | E12: SAMPLE_WEIGHT_TOO_LOW | F12: =VLOOKUP($A12,name_ID!$A$2:$B$401,2,FALSE) -> B4I_2025_NY_5073
A13: 735053 | B13: 9.2024374 | C13: Oats | D13: 45909.478 | E13: NO_ERROR | F13: =VLOOKUP($A13,name_ID!$A$2:$B$401,2,FALSE) -> B4I_2025_NY_5197
... A342: 734863 | B342: 10.389804 | C342: Oats | D342: 46000.661 | E342: SAMPLE_WEIGHT_TOO_LOW | F342: =VLOOKUP($A342,name_ID!$A$2:$B$401,2,FALSE) -> B4I_2025_NY_5088
A343: 734770 | B343: 9.4486646 | C343: Oats | D343: 17/09/2025 11:23 | E343: SAMPLE_WEIGHT_TOO_LOW | F343: =VLOOKUP($A343,name_ID!$A$2:$B$401,2,FALSE) -> B4I_2025_NY_5062
A344: 735039 | B344: 9.6384835 | C344: Oats | D344: 17/09/2025 11:24 | E344: SAMPLE_WEIGHT_TOO_LOW | F344: =VLOOKUP($A344,name_ID!$A$2:$B$401,2,FALSE) -> B4I_2025_NY_5216
A345: 735108 | B345: 9.4416713 | C345: Oats | D345: 17/09/2025 11:24 | E345: SAMPLE_WEIGHT_TOO_LOW | F345: =VLOOKUP($A345,name_ID!$A$2:$B$401,2,FALSE) -> B4I_2025_NY_5308
A346: 734996 | B346: 9.1225259 | C346: Oats | D346: 17/09/2025 11:25 | E346: NO_ERROR | F346: =VLOOKUP($A346,name_ID!$A$2:$B$401,2,FALSE) -> B4I_2025_NY_5214
A347: 734847 | B347: 9.2439402 | C347: Oats | D347: 17/09/2025 11:26 | E347: NO_ERROR | F347: =VLOOKUP($A347,name_ID!$A$2:$B$401,2,FALSE) -> B4I_2025_NY_5316
A348: 734851 | B348: 8.9273183 | C348: Oats | D348: 17/09/2025 11:27 | E348: NO_ERROR | F348: =VLOOKUP($A348,name_ID!$A$2:$B$401,2,FALSE) -> B4I_2025_NY_5247
A349: 734950 | B349: 8.9975565 | C349: Oats | D349: 17/09/2025 11:27 | E349: NO_ERROR | F349: =VLOOKUP($A349,name_ID!$A$2:$B$401,2,FALSE) -> B4I_2025_NY_5387
A350: 734772 | B350: 9.1279224 | C350: Oats | D350: 17/09/2025 11:28 | E350: NO_ERROR | F350: =VLOOKUP($A350,name_ID!$A$2:$B$401,2,FALSE) -> B4I_2025_NY_5114
A351: 734858 | B351: 10.020455 | C351: Oats | D351: 17/09/2025 11:29 | E351: SAMPLE_WEIGHT_TOO_LOW | F351: =VLOOKUP($A351,name_ID!$A$2:$B$401,2,FALSE) -> B4I_2025_NY_5064
A352: 735015 | B352: 9.2432429 | C352: Oats | D352: 17/09/2025 11:30 | E352: SAMPLE_WEIGHT_TOO_LOW | F352: =VLOOKUP($A352,name_ID!$A$2:$B$401,2,FALSE) -> B4I_2025_NY_5235
A353: 734732 | B353: 9.0806407 | C353: Oats | D353: 17/09/2025 11:30 | E353: SAMPLE_WEIGHT_TOO_LOW | F353: =VLOOKUP($A353,name_ID!$A$2:$B$401,2,FALSE) -> B4I_2025_NY_5136
A354: 734911 | B354: 9.0943381 | C354: Oats | D354: 17/09/2025 11:32 | E354: NO_ERROR | F354: =VLOOKUP($A354,name_ID!$A$2:$B$401,2,FALSE) -> B4I_2025_NY_5187
... A433: 734947 | B433: 8.7466838 | C433: Oats | D433: 17/09/2025 12:48 | E433: NO_ERROR | F433: =VLOOKUP($A433,name_ID!$A$2:$B$401,2,FALSE) -> B4I_2025_NY_5141

Sheet oat_test
A1: SampleId | B1: Test weight lbs/bu | C1: Product | D1: DateTime | E1: Error | F1: observationUnitName | G1: Test weight - g/L|CO_350:0000259
A2: 734992 | B2: 42.293431 | C2: Oats | D2: 45909.467 | E2: NO_ERROR | F2: =VLOOKUP($A2,name_ID!$A$2:$B$401,2,FALSE) -> B4I_2025_NY_5299 | G2: =B2*12.87186 -> 544.39513
A3: 735007 | B3: 38.09714 | C3: Oats | D3: 45909.47 | E3: NO_ERROR | F3: =VLOOKUP($A3,name_ID!$A$2:$B$401,2,FALSE) -> B4I_2025_NY_5151 | G3: =B3*12.87186 -> 490.38105
A4: 734844 | B4: 32.670009 | C4: Oats | D4: 45909.471 | E4: SAMPLE_WEIGHT_TOO_LOW | F4: =VLOOKUP($A4,name_ID!$A$2:$B$401,2,FALSE) -> B4I_2025_NY_5105 | G4: =B4*12.87186 -> 420.52378
A5: 734845 | B5: 32.762548 | C5: Oats | D5: 45909.472 | E5: SAMPLE_WEIGHT_TOO_LOW | F5: =VLOOKUP($A5,name_ID!$A$2:$B$401,2,FALSE) -> B4I_2025_NY_5172 | G5: =B5*12.87186 -> 421.71494
A6: 734737 | B6: 37.522248 | C6: Oats | D6: 45909.472 | E6: NO_ERROR | F6: =VLOOKUP($A6,name_ID!$A$2:$B$401,2,FALSE) -> B4I_2025_NY_5156 | G6: =B6*12.87186 -> 482.98112
A7: 734945 | B7: 26.481693 | C7: Oats | D7: 45909.473 | E7: SAMPLE_WEIGHT_TOO_LOW | F7: =VLOOKUP($A7,name_ID!$A$2:$B$401,2,FALSE) -> B4I_2025_NY_5045 | G7: =B7*12.87186 -> 340.86865
A8: 734861 | B8: 40.420891 | C8: Oats | D8: 45909.474 | E8: NO_ERROR | F8: =VLOOKUP($A8,name_ID!$A$2:$B$401,2,FALSE) -> B4I_2025_NY_5153 | G8: =B8*12.87186 -> 520.29205
A9: 734853 | B9: 33.680542 | C9: Oats | D9: 45909.474 | E9: SAMPLE_WEIGHT_TOO_LOW | F9: =VLOOKUP($A9,name_ID!$A$2:$B$401,2,FALSE) -> B4I_2025_NY_5280 | G9: =B9*12.87186 -> 433.53123
A10: 735096 | B10: 35.847375 | C10: Oats | D10: 45909.475 | E10: NO_ERROR | F10: =VLOOKUP($A10,name_ID!$A$2:$B$401,2,FALSE) -> B4I_2025_NY_5006 | G10: =B10*12.87186 -> 461.42239
A11: 734929 | B11: 37.545548 | C11: Oats | D11: 45909.477 | E11: NO_ERROR | F11: =VLOOKUP($A11,name_ID!$A$2:$B$401,2,FALSE) -> B4I_2025_NY_5120 | G11: =B11*12.87186 -> 483.28104
A12: 735026 | B12: 27.071935 | C12: Oats | D12: 45909.478 | E12: SAMPLE_WEIGHT_TOO_LOW | F12: =VLOOKUP($A12,name_ID!$A$2:$B$401,2,FALSE) -> B4I_2025_NY_5073 | G12: =B12*12.87186 -> 348.46616
A13: 735053 | B13: 35.415709 | C13: Oats | D13: 45909.478 | E13: NO_ERROR | F13: =VLOOKUP($A13,name_ID!$A$2:$B$401,2,FALSE) -> B4I_2025_NY_5197 | G13: =B13*12.87186 -> 455.86605
... A331: 734944 | B331: 29.680703 | C331: Oats | D331: 46000.654 | E331: SAMPLE_WEIGHT_TOO_LOW | F331: =VLOOKUP($A331,name_ID!$A$2:$B$401,2,FALSE) -> B4I_2025_NY_5059 | G331: =B331*12.87186 -> 382.04586
A332: test | B332: 30.830377 | C332: Oats | D332: 46000.655 | E332: SAMPLE_WEIGHT_TOO_LOW | F332: =VLOOKUP($A332,name_ID!$A$2:$B$401,2,FALSE) -> #N/A | G332: =B332*12.87186 -> 396.84429
A333: 734716 | B333: 30.029658 | C333: Oats | D333: 46000.656 | E333: SAMPLE_WEIGHT_TOO_LOW | F333: =VLOOKUP($A333,name_ID!$A$2:$B$401,2,FALSE) -> B4I_2025_NY_5058 | G333: =B333*12.87186 -> 386.53755
A334: 734817 | B334: 31.76869 | C334: Oats | D334: 46000.656 | E334: SAMPLE_WEIGHT_TOO_LOW | F334: =VLOOKUP($A334,name_ID!$A$2:$B$401,2,FALSE) -> B4I_2025_NY_5143 | G334: =B334*12.87186 -> 408.92213
A335: 735070 | B335: 34.116625 | C335: Oats | D335: 46000.656 | E335: SAMPLE_WEIGHT_TOO_LOW | F335: =VLOOKUP($A335,name_ID!$A$2:$B$401,2,FALSE) -> B4I_2025_NY_5109 | G335: =B335*12.87186 -> 439.14443
A336: 734893 | B336: 33.750444 | C336: Oats | D336: 46000.657 | E336: SAMPLE_WEIGHT_TOO_LOW | F336: =VLOOKUP($A336,name_ID!$A$2:$B$401,2,FALSE) -> B4I_2025_NY_5089 | G336: =B336*12.87186 -> 434.43099
A337: 734837 | B337: 29.741881 | C337: Oats | D337: 46000.658 | E337: SAMPLE_WEIGHT_TOO_LOW | F337: =VLOOKUP($A337,name_ID!$A$2:$B$401,2,FALSE) -> B4I_2025_NY_5112 | G337: =B337*12.87186 -> 382.83333
A338: 734864 | B338: 30.955603 | C338: Oats | D338: 46000.658 | E338: SAMPLE_WEIGHT_TOO_LOW | F338: =VLOOKUP($A338,name_ID!$A$2:$B$401,2,FALSE) -> B4I_2025_NY_5104 | G338: =B338*12.87186 -> 398.45619
A339: 734743 | B339: 33.427992 | C339: Oats | D339: 46000.658 | E339: SAMPLE_WEIGHT_TOO_LOW | F339: =VLOOKUP($A339,name_ID!$A$2:$B$401,2,FALSE) -> B4I_2025_NY_5008 | G339: =B339*12.87186 -> 430.28043
A340: 735102 | B340: 27.022463 | C340: Oats | D340: 46000.659 | E340: SAMPLE_WEIGHT_TOO_LOW | F340: =VLOOKUP($A340,name_ID!$A$2:$B$401,2,FALSE) -> B4I_2025_NY_5357 | G340: =B340*12.87186 -> 347.82936
A341: 734921 | B341: 34.099951 | C341: Oats | D341: 46000.66 | E341: SAMPLE_WEIGHT_TOO_LOW | F341: =VLOOKUP($A341,name_ID!$A$2:$B$401,2,FALSE) -> B4I_2025_NY_5054 | G341: =B341*12.87186 -> 438.92979
A342: 734972 | B342: 31.863217 | C342: Oats | D342: 46000.66 | E342: SAMPLE_WEIGHT_TOO_LOW | F342: =VLOOKUP($A342,name_ID!$A$2:$B$401,2,FALSE) -> B4I_2025_NY_5005 | G342: =B342*12.87186 -> 410.13887
A343: 735004 | B343: 34.514611 | C343: Oats | D343: 46000.66 | E343: SAMPLE_WEIGHT_TOO_LOW | F343: =VLOOKUP($A343,name_ID!$A$2:$B$401,2,FALSE) -> B4I_2025_NY_5076 | G343: =B343*12.87186 -> 444.26724
A344: 734863 | B344: 30.796365 | C344: Oats | D344: 46000.661 | E344: SAMPLE_WEIGHT_TOO_LOW | F344: =VLOOKUP($A344,name_ID!$A$2:$B$401,2,FALSE) -> B4I_2025_NY_5088 | G344: =B344*12.87186 -> 396.4065
A345: 734770 | B345: 25.843194 | C345: Oats | D345: 17/09/2025 11:23 | E345: SAMPLE_WEIGHT_TOO_LOW | F345: =VLOOKUP($A345,name_ID!$A$2:$B$401,2,FALSE) -> B4I_2025_NY_5062 | G345: =B345*12.87186 -> 332.64998
A346: 735108 | B346: 28.8272 | C346: Oats | D346: 17/09/2025 11:24 | E346: SAMPLE_WEIGHT_TOO_LOW | F346: =VLOOKUP($A346,name_ID!$A$2:$B$401,2,FALSE) -> B4I_2025_NY_5308 | G346: =B346*12.87186 -> 371.05968
A347: 735039 | B347: 32.037805 | C347: Oats | D347: 17/09/2025 11:24 | E347: SAMPLE_WEIGHT_TOO_LOW | F347: =VLOOKUP($A347,name_ID!$A$2:$B$401,2,FALSE) -> B4I_2025_NY_5216 | G347: =B347*12.87186 -> 412.38614
A348: 734996 | B348: 36.87392 | C348: Oats | D348: 17/09/2025 11:25 | E348: NO_ERROR | F348: =VLOOKUP($A348,name_ID!$A$2:$B$401,2,FALSE) -> B4I_2025_NY_5214 | G348: =B348*12.87186 -> 474.63594
A349: 734847 | B349: 38.250415 | C349: Oats | D349: 17/09/2025 11:26 | E349: NO_ERROR | F349: =VLOOKUP($A349,name_ID!$A$2:$B$401,2,FALSE) -> B4I_2025_NY_5316 | G349: =B349*12.87186 -> 492.35398
A350: 734851 | B350: 35.845829 | C350: Oats | D350: 17/09/2025 11:27 | E350: NO_ERROR | F350: =VLOOKUP($A350,name_ID!$A$2:$B$401,2,FALSE) -> B4I_2025_NY_5247 | G350: =B350*12.87186 -> 461.40249
A351: 734950 | B351: 39.465793 | C351: Oats | D351: 17/09/2025 11:27 | E351: NO_ERROR | F351: =VLOOKUP($A351,name_ID!$A$2:$B$401,2,FALSE) -> B4I_2025_NY_5387 | G351: =B351*12.87186 -> 507.99817
A352: 734772 | B352: 42.686447 | C352: Oats | D352: 17/09/2025 11:28 | E352: NO_ERROR | F352: =VLOOKUP($A352,name_ID!$A$2:$B$401,2,FALSE) -> B4I_2025_NY_5114 | G352: =B352*12.87186 -> 549.45397
A353: 734858 | B353: 29.500704 | C353: Oats | D353: 17/09/2025 11:29 | E353: SAMPLE_WEIGHT_TOO_LOW | F353: =VLOOKUP($A353,name_ID!$A$2:$B$401,2,FALSE) -> B4I_2025_NY_5064 | G353: =B353*12.87186 -> 379.72894
A354: 735015 | B354: 33.200177 | C354: Oats | D354: 17/09/2025 11:30 | E354: SAMPLE_WEIGHT_TOO_LOW | F354: =VLOOKUP($A354,name_ID!$A$2:$B$401,2,FALSE) -> B4I_2025_NY_5235 | G354: =B354*12.87186 -> 427.34804
A355: 734732 | B355: 34.497273 | C355: Oats | D355: 17/09/2025 11:30 | E355: SAMPLE_WEIGHT_TOO_LOW | F355: =VLOOKUP($A355,name_ID!$A$2:$B$401,2,FALSE) -> B4I_2025_NY_5136 | G355: =B355*12.87186 -> 444.04407
A356: 734911 | B356: 41.200297 | C356: Oats | D356: 17/09/2025 11:32 | E356: NO_ERROR | F356: =VLOOKUP($A356,name_ID!$A$2:$B$401,2,FALSE) -> B4I_2025_NY_5187 | G356: =B356*12.87186 -> 530.32446
... A435: 734947 | B435: 42.156941 | C435: Oats | D435: 17/09/2025 12:48 | E435: NO_ERROR | F435: =VLOOKUP($A435,name_ID!$A$2:$B$401,2,FALSE) -> B4I_2025_NY_5141 | G435: =B435*12.87186 -> 542.63825

Sheet missing_oat
A1: observationUnitName
A2: B4I_2025_NY_5001 | B2: 1
A3: B4I_2025_NY_5002 | B3: 2
A4: B4I_2025_NY_5003 | B4: 3
A5: B4I_2025_NY_5004 | B5: 4
A6: B4I_2025_NY_5005 | B6: 5
A7: B4I_2025_NY_5006 | B7: 6
A8: B4I_2025_NY_5007 | B8: 7
A9: B4I_2025_NY_5008 | B9: 8
A10: B4I_2025_NY_5009 | B10: 9
A11: B4I_2025_NY_5010 | B11: 10
A12: B4I_2025_NY_5011 | B12: 11
A13: B4I_2025_NY_5012 | B13: 12
... A17: B4I_2025_NY_5016 | B17: 16
B18: 17
A19: B4I_2025_NY_5018 | B19: 18
A20: B4I_2025_NY_5019 | B20: 19
A21: B4I_2025_NY_5020 | B21: 20
A22: B4I_2025_NY_5021 | B22: 21
A23: B4I_2025_NY_5022 | B23: 22
A24: B4I_2025_NY_5023 | B24: 23
A25: B4I_2025_NY_5024 | B25: 24
A26: B4I_2025_NY_5025 | B26: 25
A27: B4I_2025_NY_5026 | B27: 26
A28: B4I_2025_NY_5027 | B28: 27
B29: 28
A30: B4I_2025_NY_5029 | B30: 29
A31: B4I_2025_NY_5030 | B31: 30
A32: B4I_2025_NY_5031 | B32: 31
A33: B4I_2025_NY_5032 | B33: 32
A34: B4I_2025_NY_5033 | B34: 33
A35: B4I_2025_NY_5034 | B35: 34
A36: B4I_2025_NY_5035 | B36: 35
A37: B4I_2025_NY_5036 | B37: 36
A38: B4I_2025_NY_5037 | B38: 37
A39: B4I_2025_NY_5038 | B39: 38
A40: B4I_2025_NY_5039 | B40: 39
A41: B4I_2025_NY_5040 | B41: 40
... A107: B4I_2025_NY_5106 | B107: 106
B108: 107
...

Sheet pea_moist_TW
A1: SampleId | B1: Pea Grain Moisture Content - %|CO_xxx:0003018 | C1: TestWeight | D1: Temperature | E1: Product | F1: observationUnitName | G1: Test weight - g/L|CO_350:0000259
A2: 735022 | B2: 9.2641059 | C2: 81.754015 | D2: 29.714445 | E2: Peas Smooth | F2: =VLOOKUP($A2,name_ID!$A$2:$B$401,2,FALSE) -> B4I_2025_NY_5046 | G2: =C2*12.87186 -> 1052.3262
A3: 734972 | B3: 8.871686 | C3: 81.124186 | D3: 30.634445 | E3: Peas Smooth | F3: =VLOOKUP($A3,name_ID!$A$2:$B$401,2,FALSE) -> B4I_2025_NY_5005 | G3: =C3*12.87186 -> 1044.2192
A4: 735033 | B4: 9.2208868 | C4: 82.816379 | D4: 30.134445 | E4: Peas Smooth | F4: =VLOOKUP($A4,name_ID!$A$2:$B$401,2,FALSE) -> B4I_2025_NY_5362 | G4: =C4*12.87186 -> 1066.0008
A5: 734739 | B5: 9.4685212 | C5: 82.791159 | D5: 29.994445 | E5: Peas Smooth | F5: =VLOOKUP($A5,name_ID!$A$2:$B$401,2,FALSE) -> B4I_2025_NY_5009 | G5: =C5*12.87186 -> 1065.6762
A6: 735052 | B6: 10.669324 | C6: 68.370312 | D6: 27.594445 | E6: Peas Smooth | F6: =VLOOKUP($A6,name_ID!$A$2:$B$401,2,FALSE) -> B4I_2025_NY_5243 | G6: =C6*12.87186 -> 880.05308
A7: 734944 | B7: 9.8705859 | C7: 70.610253 | D7: 26.694445 | E7: Peas Smooth | F7: =VLOOKUP($A7,name_ID!$A$2:$B$401,2,FALSE) -> B4I_2025_NY_5059 | G7: =C7*12.87186 -> 908.88529
A8: 734863 | B8: 9.3808979 | C8: 80.989943 | D8: 28.514445 | E8: Peas Smooth | F8: =VLOOKUP($A8,name_ID!$A$2:$B$401,2,FALSE) -> B4I_2025_NY_5088 | G8: =C8*12.87186 -> 1042.4912
A9: 734839 | B9: 9.5631676 | C9: 81.930445 | D9: 25.614445 | E9: Peas Smooth | F9: =VLOOKUP($A9,name_ID!$A$2:$B$401,2,FALSE) -> B4I_2025_NY_5144 | G9: =C9*12.87186 -> 1054.5972
A10: 735037 | B10: 9.2625747 | C10: 80.300615 | D10: 27.394445 | E10: Peas Smooth | F10: =VLOOKUP($A10,name_ID!$A$2:$B$401,2,FALSE) -> B4I_2025_NY_5348 | G10: =C10*12.87186 -> 1033.6183
A11: 734718 | B11: 9.4054182 | C11: 82.200307 | D11: 27.494445 | E11: Peas Smooth | F11: =VLOOKUP($A11,name_ID!$A$2:$B$401,2,FALSE) -> B4I_2025_NY_5007 | G11: =C11*12.87186 -> 1058.0708
A12: 734836 | B12: 9.1052382 | C12: 82.337301 | D12: 27.414445 | E12: Peas Smooth | F12: =VLOOKUP($A12,name_ID!$A$2:$B$401,2,FALSE) -> B4I_2025_NY_5029 | G12: =C12*12.87186 -> 1059.8342
A13: 734845 | B13: 9.8449319 | C13: 73.780608 | D13: 25.614445 | E13: Peas Smooth | F13: =VLOOKUP($A13,name_ID!$A$2:$B$401,2,FALSE) -> B4I_2025_NY_5172 | G13: =C13*12.87186 -> 949.69366
... A282: 734734 | B282: 7.6413685 | C282: 82.62046 | D282: 25.734445 | E282: Peas Smooth | F282: =VLOOKUP($A282,name_ID!$A$2:$B$401,2,FALSE) -> B4I_2025_NY_5221 | G282: =C282*12.87186 -> 1063.479

Sheet maturity
A1: plot number | B1: Maturity date - Julian day|CO_350:0000271 | C1: pea maturity | D1: Pea Maturity Date - Julian Day|CO_xxx:0003015 | E1: observationUnitDbId | F1: observationUnitName
A2: 5001 | B2: 197 | C2: 204 | D2: 204 | E2: 734848 | F2: B4I_2025_NY_5001
A3: 5002 | B3: 198 | C3: 203 | D3: 203 | E3: 735081 | F3: B4I_2025_NY_5002
A4: 5003 | B4: 197 | C4: 200 | D4: 200 | E4: 734918 | F4: B4I_2025_NY_5003
A5: 5004 | B5: 198 | C5: 204 | D5: 204 | E5: 734939 | F5: B4I_2025_NY_5004
A6: 5005 | B6: 202 | C6: 205 | D6: 205 | E6: 734972 | F6: B4I_2025_NY_5005
A7: 5006 | B7: 204 | C7: 203 | D7: 203 | E7: 735096 | F7: B4I_2025_NY_5006
A8: 5007 | B8: 198 | C8: 204 | D8: 204 | E8: 734718 | F8: B4I_2025_NY_5007
A9: 5008 | B9: 204 | C9: 205 | D9: 205 | E9: 734743 | F9: B4I_2025_NY_5008
A10: 5009 | B10: 205 | C10: 205 | D10: 205 | E10: 734739 | F10: B4I_2025_NY_5009
A11: 5010 | B11: 198 | C11: 205 | D11: 205 | E11: 734726 | F11: B4I_2025_NY_5010
A12: 5011 | B12: 202 | D12: 218 | E12: 734738 | F12: B4I_2025_NY_5011
A13: 5012 | B13: 203 | C13: 203 | D13: 203 | E13: 734962 | F13: B4I_2025_NY_5012
A14: 5013 | B14: 205 | C14: 204 | D14: 204 | E14: 735035 | F14: B4I_2025_NY_5013
A15: 5014 | B15: 204 | C15: 205 | D15: 205 | E15: 735051 | F15: B4I_2025_NY_5014
A16: 5015 | B16: 203 | C16: 202 | D16: 202 | E16: 735084 | F16: B4I_2025_NY_5015
A17: 5016 | B17: 198 | C17: 205 | D17: 205 | E17: 735008 | F17: B4I_2025_NY_5016
A18: 5017 | B18: 199 | C18: 205 | D18: 205 | E18: 734832 | F18: B4I_2025_NY_5017
A19: 5018 | B19: 198 | C19: 202 | D19: 202 | E19: 734857 | F19: B4I_2025_NY_5018
A20: 5019 | B20: 200 | C20: 204 | D20: 204 | E20: 734865 | F20: B4I_2025_NY_5019
A21: 5020 | B21: 198 | C21: 202 | D21: 202 | E21: 734900 | F21: B4I_2025_NY_5020
A22: 5021 | B22: 199 | C22: 200 | D22: 200 | E22: 734866 | F22: B4I_2025_NY_5021
A23: 5022 | B23: 204 | C23: 203 | D23: 203 | E23: 735041 | F23: B4I_2025_NY_5022
A24: 5023 | B24: 205 | C24: 205 | D24: 205 | E24: 735014 | F24: B4I_2025_NY_5023
... A44: 5043 | B44: 197 | C44: 205 | D44: 205 | E44: 734997 | F44: B4I_2025_NY_5043
A45: 5044 | B45: 198 | D45: 218 | E45: 734966 | F45: B4I_2025_NY_5044
A46: 5045 | B46: 198 | C46: 205 | D46: 205 | E46: 734945 | F46: B4I_2025_NY_5045
A47: 5046 | B47: 203 | C47: 205 | D47: 205 | E47: 735022 | F47: B4I_2025_NY_5046
A48: 5047 | B48: 199 | D48: 218 | E48: 734794 | F48: B4I_2025_NY_5047
A49: 5048 | B49: 205 | C49: 205 | D49: 205 | E49: 734765 | F49: B4I_2025_NY_5048
A50: 5049 | B50: 197 | D50: 218 | E50: 734826 | F50: B4I_2025_NY_5049
A51: 5050 | B51: 197 | D51: 218 | E51: 734843 | F51: B4I_2025_NY_5050
A52: 5051 | B52: 197 | C52: 205 | D52: 205 | E52: 734828 | F52: B4I_2025_NY_5051
A53: 5052 | B53: 197 | C53: 204 | D53: 204 | E53: 735107 | F53: B4I_2025_NY_5052
A54: 5053 | B54: 199 | C54: 200 | D54: 200 | E54: 734935 | F54: B4I_2025_NY_5053
A55: 5054 | B55: 200 | C55: 204 | D55: 204 | E55: 734921 | F55: B4I_2025_NY_5054
A56: 5055 | B56: 200 | C56: 205 | D56: 205 | E56: 734988 | F56: B4I_2025_NY_5055
A57: 5056 | B57: 203 | D57: 218 | E57: 735069 | F57: B4I_2025_NY_5056
A58: 5057 | B58: 198 | C58: 207 | D58: 207 | E58: 734735 | F58: B4I_2025_NY_5057
A59: 5058 | B59: 203 | C59: 205 | D59: 205 | E59: 734716 | F59: B4I_2025_NY_5058
...

Sheet small_pea_1000
A1: Plot ID | B1: 100 Pea Weight | C1: How many peas? (blank cell=100) | D1: Pea Thousand Grain Weight - g|CO_xxx:0003017 | E1: observationUnitName
A2: 735084 | B2: 22.29 | D2: =B2*10 -> 222.9 | E2: =VLOOKUP(small_pea_1000!$A2,name_ID!$A$2:$B$401,2,FALSE) -> B4I_2025_NY_5015
A3: 735043 | B3: 20.72 | D3: =B3*10 -> 207.2 | E3: =VLOOKUP($A3,name_ID!$A$2:$B$401,2,FALSE) -> B4I_2025_NY_5223
A4: 734934 | B4: 19.47 | D4: =B4*10 -> 194.7 | E4: =VLOOKUP($A4,name_ID!$A$2:$B$401,2,FALSE) -> B4I_2025_NY_5256
A5: 734738 | B5: 19.13 | D5: =B5*10 -> 191.3 | E5: =VLOOKUP($A5,name_ID!$A$2:$B$401,2,FALSE) -> B4I_2025_NY_5011
A6: 734991 | B6: 20.94 | D6: =B6*10 -> 209.4 | E6: =VLOOKUP($A6,name_ID!$A$2:$B$401,2,FALSE) -> B4I_2025_NY_5301
A7: 735079 | B7: 19.76 | D7: =B7*10 -> 197.6 | E7: =VLOOKUP($A7,name_ID!$A$2:$B$401,2,FALSE) -> B4I_2025_NY_5075
A8: 734754 | B8: 18.82 | D8: =B8*10 -> 188.2 | E8: =VLOOKUP($A8,name_ID!$A$2:$B$401,2,FALSE) -> B4I_2025_NY_5287
A9: 734989 | B9: 21.01 | D9: =B9*10 -> 210.1 | E9: =VLOOKUP($A9,name_ID!$A$2:$B$401,2,FALSE) -> B4I_2025_NY_5378
A10: 735032 | B10: 23.05 | D10: =B10*10 -> 230.5 | E10: =VLOOKUP($A10,name_ID!$A$2:$B$401,2,FALSE) -> B4I_2025_NY_5026
A11: 734977 | B11: 24.34 | D11: =B11*10 -> 243.4 | E11: =VLOOKUP($A11,name_ID!$A$2:$B$401,2,FALSE) -> B4I_2025_NY_5101
A12: 734717 | B12: 21.16 | D12: =B12*10 -> 211.6 | E12: =VLOOKUP($A12,name_ID!$A$2:$B$401,2,FALSE) -> B4I_2025_NY_5302
A13: 734840 | B13: 18.52 | D13: =B13*10 -> 185.2 | E13: =VLOOKUP($A13,name_ID!$A$2:$B$401,2,FALSE) -> B4I_2025_NY_5394
A14: 734762 | B14: 21.27 | D14: =B14*10 -> 212.7 | E14: =VLOOKUP($A14,name_ID!$A$2:$B$401,2,FALSE) -> B4I_2025_NY_5217
... A108: 734736 | B108: 21.45 | D108: =B108*10 -> 214.5 | E108: =VLOOKUP($A108,name_ID!$A$2:$B$401,2,FALSE) -> B4I_2025_NY_5132
A109: 734832 | B109: 15.95 | C109: 78 | D109: 204.5 | E109: =VLOOKUP($A109,name_ID!$A$2:$B$401,2,FALSE) -> B4I_2025_NY_5017
A110: 734818 | B110: 16.58 | D110: =B110*10 -> 165.8 | E110: =VLOOKUP($A110,name_ID!$A$2:$B$401,2,FALSE) -> B4I_2025_NY_5248
A111: 735013 | B111: 16.78 | D111: =B111*10 -> 167.8 | E111: =VLOOKUP($A111,name_ID!$A$2:$B$401,2,FALSE) -> B4I_2025_NY_5117
A112: 734970 | B112: 17.53 | C112: 95 | D112: 184.5 | E112: =VLOOKUP($A112,name_ID!$A$2:$B$401,2,FALSE) -> B4I_2025_NY_5267
A113: 734795 | B113: 23.13 | D113: =B113*10 -> 231.3 | E113: =VLOOKUP($A113,name_ID!$A$2:$B$401,2,FALSE) -> B4I_2025_NY_5146
A114: 734905 | B114: 18.58 | D114: =B114*10 -> 185.8 | E114: =VLOOKUP($A114,name_ID!$A$2:$B$401,2,FALSE) -> B4I_2025_NY_5133
A115: 734757 | B115: 19.09 | D115: =B115*10 -> 190.9 | E115: =VLOOKUP($A115,name_ID!$A$2:$B$401,2,FALSE) -> B4I_2025_NY_5249
A116: 735092 | B116: 16.88 | D116: =B116*10 -> 168.8 | E116: =VLOOKUP($A116,name_ID!$A$2:$B$401,2,FALSE) -> B4I_2025_NY_5107
A117: 735103 | E117: =VLOOKUP($A117,name_ID!$A$2:$B$401,2,FALSE) -> B4I_2025_NY_5245
A118: 735104 | B118: 17.23 | D118: =B118*10 -> 172.3 | E118: =VLOOKUP($A118,name_ID!$A$2:$B$401,2,FALSE) -> B4I_2025_NY_5253
A119: 734732 | B119: 16.33 | D119: =B119*10 -> 163.3 | E119: =VLOOKUP($A119,name_ID!$A$2:$B$401,2,FALSE) -> B4I_2025_NY_5136
A120: 734782 | B120: 6.05 | C120: 29 | D120: 208.6 | E120: =VLOOKUP($A120,name_ID!$A$2:$B$401,2,FALSE) -> B4I_2025_NY_5028

Sheet updates
A1: observationUnitName | B1: Grain weight - g|CO_350:0005123 | C1: Grain moisture content - percent|CO_350:0000536 | D1: Test weight - g/L|CO_350:0000259 | E1: Thousand grain weight - g|CO_350:0000251 | F1: Pea Grain Weight - g|CO_xxx:0003006 | G1: Pea Grain Moisture Content - %|CO_xxx:0003018 | H1: Pea Test Weight - g/L|CO_xxx:0003016 | I1: Pea Thousand Grain Weight - g|CO_xxx:0003017
A2: B4I_2025_NY_5206 | C2: 0 | D2: 0

Sheet name_ID
A1: observationUnitDbId | B1: observationUnitName
A2: 734848 | B2: B4I_2025_NY_5001
A3: 735081 | B3: B4I_2025_NY_5002
A4: 734918 | B4: B4I_2025_NY_5003
A5: 734939 | B5: B4I_2025_NY_5004
A6: 734972 | B6: B4I_2025_NY_5005
A7: 735096 | B7: B4I_2025_NY_5006
A8: 734718 | B8: B4I_2025_NY_5007
A9: 734743 | B9: B4I_2025_NY_5008
A10: 734739 | B10: B4I_2025_NY_5009
A11: 734726 | B11: B4I_2025_NY_5010
A12: 734738 | B12: B4I_2025_NY_5011
A13: 734962 | B13: B4I_2025_NY_5012
... A401: 735083 | B401: B4I_2025_NY_5400

Sheet Sheet1
